<?xml version="1.0" encoding="utf-8"?>
<!-- This URDF was automatically created by SolidWorks to URDF Exporter! Originally created by Stephen Brawner (brawner@gmail.com) 
     Commit Version: 1.6.0-4-g7f85cfe  Build Version: 1.6.7995.38578
     For more information, please see http://wiki.ros.org/sw_urdf_exporter -->
<robot
  name="hand_rviz/urdf">
  <link
    name="hand_base_link">
    <inertial>
      <origin
        xyz="-0.00061429354910202 -0.00944665576411385 0.0223167833764774"
        rpy="0 0 0" />
      <mass
        value="1.38812640347778" />
      <inertia
        ixx="0.000445542321150216"
        ixy="3.50155988030047E-06"
        ixz="4.64398324346647E-07"
        iyy="0.000524208846276378"
        iyz="1.03345252482007E-05"
        izz="0.000497637041063157" />
    </inertial>
    <visual>
      <origin
        xyz="0 0 0"
        rpy="0 0 0" />
      <geometry>
        <mesh
          filename="package://hand_rviz/urdf/meshes/hand_base_link.STL" />
      </geometry>
      <material
        name="">
        <color
          rgba="0.792156862745098 0.819607843137255 0.933333333333333 1" />
      </material>
    </visual>
    <collision>
      <origin
        xyz="0 0 0"
        rpy="0 0 0" />
      <geometry>
        <mesh
          filename="package://hand_rviz/urdf/meshes/hand_base_link.STL" />
      </geometry>
    </collision>
  </link>
  <link
    name="tcf_link">
    <inertial>
      <origin
        xyz="-0.013539870918749 0.00696804614882354 0.000116280993402551"
        rpy="0 0 0" />
      <mass
        value="0.00484999590725353" />
      <inertia
        ixx="7.75462007985153E-07"
        ixy="2.19658485715546E-07"
        ixz="4.35849510085832E-09"
        iyy="9.62045357645233E-07"
        iyz="-1.62755706072683E-07"
        izz="6.84730747333233E-07" />
    </inertial>
    <visual>
      <origin
        xyz="0 0 0"
        rpy="0 0 0" />
      <geometry>
        <mesh
          filename="package://hand_rviz/urdf/meshes/tcf_link.STL" />
      </geometry>
      <material
        name="">
        <color
          rgba="0.792156862745098 0.819607843137255 0.933333333333333 1" />
      </material>
    </visual>
    <collision>
      <origin
        xyz="0 0 0"
        rpy="0 0 0" />
      <geometry>
        <mesh
          filename="package://hand_rviz/urdf/meshes/tcf_link.STL" />
      </geometry>
    </collision>
  </link>
  <joint
    name="tcf_joint"
    type="revolute">
    <origin
      xyz="-0.03245 -0.0217 0.0495"
      rpy="0 0 0" />
    <parent
      link="hand_base_link" />
    <child
      link="tcf_link" />
    <axis
      xyz="0 0 1" />
    <limit
      lower="-1.57"
      upper="0.175"
      effort="0"
      velocity="0" />
  </joint>
  <link
    name="tca_link">
    <inertial>
      <origin
        xyz="0.0104917903510064 -0.000676779323759157 0.00216340571913179"
        rpy="0 0 0" />
      <mass
        value="0.00499478923208696" />
      <inertia
        ixx="2.16030308030573E-07"
        ixy="1.54981546627713E-08"
        ixz="3.4127277536893E-08"
        iyy="5.06187109604147E-07"
        iyz="-6.53335217098174E-10"
        izz="5.03702828276537E-07" />
    </inertial>
    <visual>
      <origin
        xyz="0 0 0"
        rpy="0 0 0" />
      <geometry>
        <mesh
          filename="package://hand_rviz/urdf/meshes/tca_link.STL" />
      </geometry>
      <material
        name="">
        <color
          rgba="0.792156862745098 0.819607843137255 0.933333333333333 1" />
      </material>
    </visual>
    <collision>
      <origin
        xyz="0 0 0"
        rpy="0 0 0" />
      <geometry>
        <mesh
          filename="package://hand_rviz/urdf/meshes/tca_link.STL" />
      </geometry>
    </collision>
  </link>
  <joint
    name="tca_joint"
    type="revolute">
    <origin
      xyz="-0.024 0.01695 0.011491"
      rpy="2.8032 -1.0121 1.9642" />
    <parent
      link="tcf_link" />
    <child
      link="tca_link" />
    <axis
      xyz="0 0 1" />
    <limit
      lower="-0.5"
      upper="1"
      effort="0"
      velocity="0" />
  </joint>
  <link
    name="tma_link">
    <inertial>
      <origin
        xyz="0.00971662082317795 6.7890478227535E-05 0.000726629607537624"
        rpy="0 0 0" />
      <mass
        value="0.00320272686969075" />
      <inertia
        ixx="9.80474055431482E-08"
        ixy="-2.05206873883352E-09"
        ixz="5.83406243383443E-09"
        iyy="1.89906799468114E-07"
        iyz="-8.17308371542074E-11"
        izz="1.95297660560772E-07" />
    </inertial>
    <visual>
      <origin
        xyz="0 0 0"
        rpy="0 0 0" />
      <geometry>
        <mesh
          filename="package://hand_rviz/urdf/meshes/tma_link.STL" />
      </geometry>
      <material
        name="">
        <color
          rgba="0.792156862745098 0.819607843137255 0.933333333333333 1" />
      </material>
    </visual>
    <collision>
      <origin
        xyz="0 0 0"
        rpy="0 0 0" />
      <geometry>
        <mesh
          filename="package://hand_rviz/urdf/meshes/tma_link.STL" />
      </geometry>
    </collision>
  </link>
  <joint
    name="tma_joint"
    type="revolute">
    <origin
      xyz="0.025 -0.0014573 0.0001"
      rpy="-1.5708 0.27479 0" />
    <parent
      link="tca_link" />
    <child
      link="tma_link" />
    <axis
      xyz="0 0 1" />
    <limit
      lower="-1.2"
      upper="0.7"
      effort="0"
      velocity="0" />
  </joint>
  <link
    name="tmf_link">
    <inertial>
      <origin
        xyz="0.010171865697685 -0.00112023068715843 -2.35404821330443E-09"
        rpy="0 0 0" />
      <mass
        value="0.000948811114997913" />
      <inertia
        ixx="8.68411494167366E-09"
        ixy="2.91569669791614E-09"
        ixz="-1.30374967316227E-14"
        iyy="9.65825232359051E-08"
        iyz="-1.9069586142679E-14"
        izz="1.02763635257402E-07" />
    </inertial>
    <visual>
      <origin
        xyz="0 0 0"
        rpy="0 0 0" />
      <geometry>
        <mesh
          filename="package://hand_rviz/urdf/meshes/tmf_link.STL" />
      </geometry>
      <material
        name="">
        <color
          rgba="0.792156862745098 0.819607843137255 0.933333333333333 1" />
      </material>
    </visual>
    <collision>
      <origin
        xyz="0 0 0"
        rpy="0 0 0" />
      <geometry>
        <mesh
          filename="package://hand_rviz/urdf/meshes/tmf_link.STL" />
      </geometry>
    </collision>
  </link>
  <joint
    name="tmf_joint"
    type="revolute">
    <origin
      xyz="0.02 0 0.0015"
      rpy="1.5708 -0.34679 0" />
    <parent
      link="tma_link" />
    <child
      link="tmf_link" />
    <axis
      xyz="0 0 1" />
    <limit
      lower="-0.8"
      upper="1.57"
      effort="0"
      velocity="0" />
  </joint>
  <link
    name="tdf_link">
    <inertial>
      <origin
        xyz="-0.000706794999553423 -7.9780973222171E-05 -0.000112786688034917"
        rpy="0 0 0" />
      <mass
        value="0.00217689228300246" />
      <inertia
        ixx="5.19422563367913E-08"
        ixy="-1.6250540110235E-09"
        ixz="1.45574793265727E-10"
        iyy="1.78158999808894E-07"
        iyz="2.00750263449517E-11"
        izz="1.63515579779239E-07" />
    </inertial>
    <visual>
      <origin
        xyz="0 0 0"
        rpy="0 0 0" />
      <geometry>
        <mesh
          filename="package://hand_rviz/urdf/meshes/tdf_link.STL" />
      </geometry>
      <material
        name="">
        <color
          rgba="0.792156862745098 0.819607843137255 0.933333333333333 1" />
      </material>
    </visual>
    <collision>
      <origin
        xyz="0 0 0"
        rpy="0 0 0" />
      <geometry>
        <mesh
          filename="package://hand_rviz/urdf/meshes/tdf_link.STL" />
      </geometry>
    </collision>
  </link>
  <joint
    name="tdf_joint"
    type="revolute">
    <origin
      xyz="0.025 0 0"
      rpy="0 0 0.1282" />
    <parent
      link="tmf_link" />
    <child
      link="tdf_link" />
    <axis
      xyz="0 0 1" />
    <limit
      lower="0"
      upper="1.25"
      effort="0"
      velocity="0" />
  </joint>
  <link
    name="t_tip_link">
    <inertial>
      <origin
        xyz="-0.00105093780159737 0.00184221193968603 -5.55111512312578E-17"
        rpy="0 0 0" />
      <mass
        value="9.63413917384506E-05" />
      <inertia
        ixx="2.00160190678065E-09"
        ixy="6.47869811757705E-10"
        ixz="-1.12082973000935E-22"
        iyy="1.67304493693404E-09"
        iyz="-5.75439825349878E-23"
        izz="2.11896979425457E-09" />
    </inertial>
    <visual>
      <origin
        xyz="0 0 0"
        rpy="0 0 0" />
      <geometry>
        <mesh
          filename="package://hand_rviz/urdf/meshes/t_tip_link.STL" />
      </geometry>
      <material
        name="">
        <color
          rgba="0.792156862745098 0.819607843137255 0.933333333333333 1" />
      </material>
    </visual>
    <collision>
      <origin
        xyz="0 0 0"
        rpy="0 0 0" />
      <geometry>
        <mesh
          filename="package://hand_rviz/urdf/meshes/t_tip_link.STL" />
      </geometry>
    </collision>
  </link>
  <joint
    name="t_tip"
    type="fixed">
    <origin
      xyz="0.012137 0 0"
      rpy="0 0 0" />
    <parent
      link="tdf_link" />
    <child
      link="t_tip_link" />
    <axis
      xyz="0 0 0" />
  </joint>
  <link
    name="ima_link">
    <inertial>
      <origin
        xyz="0.00545951158432825 -8.86632095186204E-05 0.000675702355864649"
        rpy="0 0 0" />
      <mass
        value="0.00377097433248701" />
      <inertia
        ixx="1.92751114104043E-07"
        ixy="3.86822225253668E-09"
        ixz="1.50761022617964E-08"
        iyy="2.98859727376661E-07"
        iyz="-5.17909336999065E-10"
        izz="2.60279404999028E-07" />
    </inertial>
    <visual>
      <origin
        xyz="0 0 0"
        rpy="0 0 0" />
      <geometry>
        <mesh
          filename="package://hand_rviz/urdf/meshes/ima_link.STL" />
      </geometry>
      <material
        name="">
        <color
          rgba="0.792156862745098 0.819607843137255 0.933333333333333 1" />
      </material>
    </visual>
    <collision>
      <origin
        xyz="0 0 0"
        rpy="0 0 0" />
      <geometry>
        <mesh
          filename="package://hand_rviz/urdf/meshes/ima_link.STL" />
      </geometry>
    </collision>
  </link>
  <joint
    name="ima_joint"
    type="revolute">
    <origin
      xyz="-0.030085 -0.0405 0.11024"
      rpy="-1.5708 -1.4573 -3.1416" />
    <parent
      link="hand_base_link" />
    <child
      link="ima_link" />
    <axis
      xyz="0 0 1" />
    <limit
      lower="-0.436"
      upper="0.436"
      effort="0"
      velocity="0" />
  </joint>
  <link
    name="imf_link">
    <inertial>
      <origin
        xyz="0.0153264557799375 0.000131170231311643 -0.000214215913830931"
        rpy="0 0 0" />
      <mass
        value="0.0035062778446748" />
      <inertia
        ixx="7.49209010355308E-08"
        ixy="-2.77275284746543E-10"
        ixz="-1.59748477244705E-08"
        iyy="3.79952976568586E-07"
        iyz="4.5076371900946E-11"
        izz="3.76775898526847E-07" />
    </inertial>
    <visual>
      <origin
        xyz="0 0 0"
        rpy="0 0 0" />
      <geometry>
        <mesh
          filename="package://hand_rviz/urdf/meshes/imf_link.STL" />
      </geometry>
      <material
        name="">
        <color
          rgba="0.792156862745098 0.819607843137255 0.933333333333333 1" />
      </material>
    </visual>
    <collision>
      <origin
        xyz="0 0 0"
        rpy="0 0 0" />
      <geometry>
        <mesh
          filename="package://hand_rviz/urdf/meshes/imf_link.STL" />
      </geometry>
    </collision>
  </link>
  <joint
    name="imf_joint"
    type="revolute">
    <origin
      xyz="0.017 0 -0.000875"
      rpy="-1.5708 0 0" />
    <parent
      link="ima_link" />
    <child
      link="imf_link" />
    <axis
      xyz="0 0 1" />
    <limit
      lower="-1.57"
      upper="1.57"
      effort="0"
      velocity="0" />
  </joint>
  <link
    name="ipf_link">
    <inertial>
      <origin
        xyz="0.0110133857157522 -0.0013539573318288 4.13325360743011E-09"
        rpy="0 0 0" />
      <mass
        value="0.00108838501206663" />
      <inertia
        ixx="1.06723406101794E-08"
        ixy="4.161856826029E-09"
        ixz="1.47097799559351E-14"
        iyy="1.13635444630545E-07"
        iyz="-1.2894056068084E-14"
        izz="1.21308280596702E-07" />
    </inertial>
    <visual>
      <origin
        xyz="0 0 0"
        rpy="0 0 0" />
      <geometry>
        <mesh
          filename="package://hand_rviz/urdf/meshes/ipf_link.STL" />
      </geometry>
      <material
        name="">
        <color
          rgba="0.792156862745098 0.819607843137255 0.933333333333333 1" />
      </material>
    </visual>
    <collision>
      <origin
        xyz="0 0 0"
        rpy="0 0 0" />
      <geometry>
        <mesh
          filename="package://hand_rviz/urdf/meshes/ipf_link.STL" />
      </geometry>
    </collision>
  </link>
  <joint
    name="ipf_joint"
    type="revolute">
    <origin
      xyz="0.031 0 0"
      rpy="0 0 1.1732" />
    <parent
      link="imf_link" />
    <child
      link="ipf_link" />
    <axis
      xyz="0 0 1" />
    <limit
      lower="-0.873"
      upper="1.57"
      effort="0"
      velocity="0" />
  </joint>
  <link
    name="idf_link">
    <inertial>
      <origin
        xyz="-0.00394721683074047 -0.000117912503330819 -0.00010306810364947"
        rpy="0 0 0" />
      <mass
        value="0.00213606646468497" />
      <inertia
        ixx="5.3704768389118E-08"
        ixy="-1.93680982279683E-09"
        ixz="8.38611839998589E-10"
        iyy="1.74117816677213E-07"
        iyz="2.63400446821E-11"
        izz="1.56263328704583E-07" />
    </inertial>
    <visual>
      <origin
        xyz="0 0 0"
        rpy="0 0 0" />
      <geometry>
        <mesh
          filename="package://hand_rviz/urdf/meshes/idf_link.STL" />
      </geometry>
      <material
        name="">
        <color
          rgba="0.792156862745098 0.819607843137255 0.933333333333333 1" />
      </material>
    </visual>
    <collision>
      <origin
        xyz="0 0 0"
        rpy="0 0 0" />
      <geometry>
        <mesh
          filename="package://hand_rviz/urdf/meshes/idf_link.STL" />
      </geometry>
    </collision>
  </link>
  <joint
    name="idf_joint"
    type="revolute">
    <origin
      xyz="0.02618 0 0"
      rpy="0 0 0.39762" />
    <parent
      link="ipf_link" />
    <child
      link="idf_link" />
    <axis
      xyz="0 0 1" />
    <limit
      lower="0"
      upper="1.25"
      effort="0"
      velocity="0" />
  </joint>
  <link
    name="i_tip_link">
    <inertial>
      <origin
        xyz="-0.00104592121213919 0.0018422237895932 -2.22478285794026E-16"
        rpy="0 0 0" />
      <mass
        value="9.6341391738565E-05" />
      <inertia
        ixx="2.00160190678836E-09"
        ixy="6.47869811756371E-10"
        ixz="-1.91247415125344E-23"
        iyy="1.67304493693434E-09"
        iyz="9.93617980697945E-24"
        izz="2.11896979425816E-09" />
    </inertial>
    <visual>
      <origin
        xyz="0 0 0"
        rpy="0 0 0" />
      <geometry>
        <mesh
          filename="package://hand_rviz/urdf/meshes/i_tip_link.STL" />
      </geometry>
      <material
        name="">
        <color
          rgba="0.792156862745098 0.819607843137255 0.933333333333333 1" />
      </material>
    </visual>
    <collision>
      <origin
        xyz="0 0 0"
        rpy="0 0 0" />
      <geometry>
        <mesh
          filename="package://hand_rviz/urdf/meshes/i_tip_link.STL" />
      </geometry>
    </collision>
  </link>
  <joint
    name="i_tip"
    type="fixed">
    <origin
      xyz="0.0091323 0 0"
      rpy="0 0 0" />
    <parent
      link="idf_link" />
    <child
      link="i_tip_link" />
    <axis
      xyz="0 0 0" />
  </joint>
  <link
    name="mma_link">
    <inertial>
      <origin
        xyz="0.00545950849170132 -8.86601109218194E-05 0.000675701372274671"
        rpy="0 0 0" />
      <mass
        value="0.00377096877435373" />
      <inertia
        ixx="1.927510016226E-07"
        ixy="3.86819116341496E-09"
        ixz="1.50761562051395E-08"
        iyy="2.98859651077226E-07"
        iyz="-5.17843628266035E-10"
        izz="2.60279335278557E-07" />
    </inertial>
    <visual>
      <origin
        xyz="0 0 0"
        rpy="0 0 0" />
      <geometry>
        <mesh
          filename="package://hand_rviz/urdf/meshes/mma_link.STL" />
      </geometry>
      <material
        name="">
        <color
          rgba="0.792156862745098 0.819607843137255 0.933333333333333 1" />
      </material>
    </visual>
    <collision>
      <origin
        xyz="0 0 0"
        rpy="0 0 0" />
      <geometry>
        <mesh
          filename="package://hand_rviz/urdf/meshes/mma_link.STL" />
      </geometry>
    </collision>
  </link>
  <joint
    name="mma_joint"
    type="revolute">
    <origin
      xyz="-0.010267 -0.0405 0.12046"
      rpy="-1.5708 -1.5272 -3.1416" />
    <parent
      link="hand_base_link" />
    <child
      link="mma_link" />
    <axis
      xyz="0 0 1" />
    <limit
      lower="-0.436"
      upper="0.436"
      effort="0"
      velocity="0" />
  </joint>
  <link
    name="mmf_link">
    <inertial>
      <origin
        xyz="0.0153264556897269 0.000131170217745144 -0.000214215930973235"
        rpy="0 0 0" />
      <mass
        value="0.0035062779381524" />
      <inertia
        ixx="7.4920901109795E-08"
        ixy="-2.7727486019509E-10"
        ixz="-1.59748485638189E-08"
        iyy="3.79952977330562E-07"
        iyz="4.50761274008323E-11"
        izz="3.76775899218745E-07" />
    </inertial>
    <visual>
      <origin
        xyz="0 0 0"
        rpy="0 0 0" />
      <geometry>
        <mesh
          filename="package://hand_rviz/urdf/meshes/mmf_link.STL" />
      </geometry>
      <material
        name="">
        <color
          rgba="0.792156862745098 0.819607843137255 0.933333333333333 1" />
      </material>
    </visual>
    <collision>
      <origin
        xyz="0 0 0"
        rpy="0 0 0" />
      <geometry>
        <mesh
          filename="package://hand_rviz/urdf/meshes/mmf_link.STL" />
      </geometry>
    </collision>
  </link>
  <joint
    name="mmf_joint"
    type="revolute">
    <origin
      xyz="0.017 0 -0.000875"
      rpy="-1.5708 0 0" />
    <parent
      link="mma_link" />
    <child
      link="mmf_link" />
    <axis
      xyz="0 0 1" />
    <limit
      lower="-1.57"
      upper="1.57"
      effort="0"
      velocity="0" />
  </joint>
  <link
    name="mpf_link">
    <inertial>
      <origin
        xyz="0.0110133857157522 -0.0013539573318288 4.13325359376916E-09"
        rpy="0 0 0" />
      <mass
        value="0.00108838501206664" />
      <inertia
        ixx="1.06723406101795E-08"
        ixy="4.16185682602903E-09"
        ixz="1.47097800929716E-14"
        iyy="1.13635444630546E-07"
        iyz="-1.28940560733662E-14"
        izz="1.21308280596703E-07" />
    </inertial>
    <visual>
      <origin
        xyz="0 0 0"
        rpy="0 0 0" />
      <geometry>
        <mesh
          filename="package://hand_rviz/urdf/meshes/mpf_link.STL" />
      </geometry>
      <material
        name="">
        <color
          rgba="0.792156862745098 0.819607843137255 0.933333333333333 1" />
      </material>
    </visual>
    <collision>
      <origin
        xyz="0 0 0"
        rpy="0 0 0" />
      <geometry>
        <mesh
          filename="package://hand_rviz/urdf/meshes/mpf_link.STL" />
      </geometry>
    </collision>
  </link>
  <joint
    name="mpf_joint"
    type="revolute">
    <origin
      xyz="0.031 0 0"
      rpy="0 0 1.1732" />
    <parent
      link="mmf_link" />
    <child
      link="mpf_link" />
    <axis
      xyz="0 0 1" />
    <limit
      lower="-0.873"
      upper="1.57"
      effort="0"
      velocity="0" />
  </joint>
  <link
    name="mdf_link">
    <inertial>
      <origin
        xyz="-0.00394721684620039 -0.000117912464608128 -0.000103068054280695"
        rpy="0 0 0" />
      <mass
        value="0.00213606647535568" />
      <inertia
        ixx="5.37047707729127E-08"
        ixy="-1.93681092637364E-09"
        ixz="8.38611194263258E-10"
        iyy="1.74117815271046E-07"
        iyz="2.63402321380885E-11"
        izz="1.56263329372874E-07" />
    </inertial>
    <visual>
      <origin
        xyz="0 0 0"
        rpy="0 0 0" />
      <geometry>
        <mesh
          filename="package://hand_rviz/urdf/meshes/mdf_link.STL" />
      </geometry>
      <material
        name="">
        <color
          rgba="0.792156862745098 0.819607843137255 0.933333333333333 1" />
      </material>
    </visual>
    <collision>
      <origin
        xyz="0 0 0"
        rpy="0 0 0" />
      <geometry>
        <mesh
          filename="package://hand_rviz/urdf/meshes/mdf_link.STL" />
      </geometry>
    </collision>
  </link>
  <joint
    name="mdf_joint"
    type="revolute">
    <origin
      xyz="0.02618 0 0"
      rpy="0 0 0.39762" />
    <parent
      link="mpf_link" />
    <child
      link="mdf_link" />
    <axis
      xyz="0 0 1" />
    <limit
      lower="0"
      upper="1.25"
      effort="0"
      velocity="0" />
  </joint>
  <link
    name="m_tip_link">
    <inertial>
      <origin
        xyz="-0.00104592121213915 0.00184222378959342 -4.40945023549855E-16"
        rpy="0 0 0" />
      <mass
        value="9.63413917385605E-05" />
      <inertia
        ixx="2.0016019067882E-09"
        ixy="6.47869811756382E-10"
        ixz="5.24862299752905E-24"
        iyy="1.67304493693433E-09"
        iyz="-1.38679189130499E-23"
        izz="2.11896979425803E-09" />
    </inertial>
    <visual>
      <origin
        xyz="0 0 0"
        rpy="0 0 0" />
      <geometry>
        <mesh
          filename="package://hand_rviz/urdf/meshes/m_tip_link.STL" />
      </geometry>
      <material
        name="">
        <color
          rgba="0.792156862745098 0.819607843137255 0.933333333333333 1" />
      </material>
    </visual>
    <collision>
      <origin
        xyz="0 0 0"
        rpy="0 0 0" />
      <geometry>
        <mesh
          filename="package://hand_rviz/urdf/meshes/m_tip_link.STL" />
      </geometry>
    </collision>
  </link>
  <joint
    name="m_tip"
    type="fixed">
    <origin
      xyz="0.0091323 0 0"
      rpy="0 0 0" />
    <parent
      link="mdf_link" />
    <child
      link="m_tip_link" />
    <axis
      xyz="0 0 0" />
  </joint>
  <link
    name="rma_link">
    <inertial>
      <origin
        xyz="0.00545951269553185 -8.86616255767764E-05 0.000675699929609706"
        rpy="0 0 0" />
      <mass
        value="0.00377097155039619" />
      <inertia
        ixx="1.92751094137635E-07"
        ixy="3.86811200554875E-09"
        ixz="1.5076223370178E-08"
        iyy="2.98859812161307E-07"
        iyz="-5.17724319697699E-10"
        izz="2.60279479059688E-07" />
    </inertial>
    <visual>
      <origin
        xyz="0 0 0"
        rpy="0 0 0" />
      <geometry>
        <mesh
          filename="package://hand_rviz/urdf/meshes/rma_link.STL" />
      </geometry>
      <material
        name="">
        <color
          rgba="0.792156862745098 0.819607843137255 0.933333333333333 1" />
      </material>
    </visual>
    <collision>
      <origin
        xyz="0 0 0"
        rpy="0 0 0" />
      <geometry>
        <mesh
          filename="package://hand_rviz/urdf/meshes/rma_link.STL" />
      </geometry>
    </collision>
  </link>
  <joint
    name="rma_joint"
    type="revolute">
    <origin
      xyz="0.010267 -0.0405 0.12046"
      rpy="1.5708 -1.5272 0" />
    <parent
      link="hand_base_link" />
    <child
      link="rma_link" />
    <axis
      xyz="0 0 1" />
    <limit
      lower="-0.436"
      upper="0.436"
      effort="0"
      velocity="0" />
  </joint>
  <link
    name="rmf_link">
    <inertial>
      <origin
        xyz="0.0153264556311606 0.000131170224199759 -0.000214215922257998"
        rpy="0 0 0" />
      <mass
        value="0.00350627800305113" />
      <inertia
        ixx="7.49209011449323E-08"
        ixy="-2.77274109498896E-10"
        ixz="-1.59748486218069E-08"
        iyy="3.79952978018082E-07"
        iyz="4.50759710300356E-11"
        izz="3.76775899854073E-07" />
    </inertial>
    <visual>
      <origin
        xyz="0 0 0"
        rpy="0 0 0" />
      <geometry>
        <mesh
          filename="package://hand_rviz/urdf/meshes/rmf_link.STL" />
      </geometry>
      <material
        name="">
        <color
          rgba="0.792156862745098 0.819607843137255 0.933333333333333 1" />
      </material>
    </visual>
    <collision>
      <origin
        xyz="0 0 0"
        rpy="0 0 0" />
      <geometry>
        <mesh
          filename="package://hand_rviz/urdf/meshes/rmf_link.STL" />
      </geometry>
    </collision>
  </link>
  <joint
    name="rmf_joint"
    type="revolute">
    <origin
      xyz="0.017 0 -0.000875"
      rpy="-1.5708 0 0" />
    <parent
      link="rma_link" />
    <child
      link="rmf_link" />
    <axis
      xyz="0 0 1" />
    <limit
      lower="-1.57"
      upper="1.57"
      effort="0"
      velocity="0" />
  </joint>
  <link
    name="rpf_link">
    <inertial>
      <origin
        xyz="0.0110133857157522 -0.00135395733182886 4.13325358357766E-09"
        rpy="0 0 0" />
      <mass
        value="0.00108838501206664" />
      <inertia
        ixx="1.06723406101795E-08"
        ixy="4.16185682602892E-09"
        ixz="1.47097800308918E-14"
        iyy="1.13635444630547E-07"
        iyz="-1.28940560734154E-14"
        izz="1.21308280596703E-07" />
    </inertial>
    <visual>
      <origin
        xyz="0 0 0"
        rpy="0 0 0" />
      <geometry>
        <mesh
          filename="package://hand_rviz/urdf/meshes/rpf_link.STL" />
      </geometry>
      <material
        name="">
        <color
          rgba="0.792156862745098 0.819607843137255 0.933333333333333 1" />
      </material>
    </visual>
    <collision>
      <origin
        xyz="0 0 0"
        rpy="0 0 0" />
      <geometry>
        <mesh
          filename="package://hand_rviz/urdf/meshes/rpf_link.STL" />
      </geometry>
    </collision>
  </link>
  <joint
    name="rpf_joint"
    type="revolute">
    <origin
      xyz="0.031 0 0"
      rpy="0 0 1.17317577259539" />
    <parent
      link="rmf_link" />
    <child
      link="rpf_link" />
    <axis
      xyz="0 0 1" />
    <limit
      lower="-0.873"
      upper="1.57"
      effort="0"
      velocity="0" />
  </joint>
  <link
    name="rdf_link">
    <inertial>
      <origin
        xyz="-0.00394721685418632 -0.000117912489628058 -0.000103068004632037"
        rpy="0 0 0" />
      <mass
        value="0.002136066487395" />
      <inertia
        ixx="5.37047728994674E-08"
        ixy="-1.93681073233007E-09"
        ixz="8.3861055476539E-10"
        iyy="1.74117814198901E-07"
        iyz="2.63403970018723E-11"
        izz="1.5626333008088E-07" />
    </inertial>
    <visual>
      <origin
        xyz="0 0 0"
        rpy="0 0 0" />
      <geometry>
        <mesh
          filename="package://hand_rviz/urdf/meshes/rdf_link.STL" />
      </geometry>
      <material
        name="">
        <color
          rgba="0.792156862745098 0.819607843137255 0.933333333333333 1" />
      </material>
    </visual>
    <collision>
      <origin
        xyz="0 0 0"
        rpy="0 0 0" />
      <geometry>
        <mesh
          filename="package://hand_rviz/urdf/meshes/rdf_link.STL" />
      </geometry>
    </collision>
  </link>
  <joint
    name="rdf_joint"
    type="revolute">
    <origin
      xyz="0.02618 0 0"
      rpy="0 0 0.397620554199504" />
    <parent
      link="rpf_link" />
    <child
      link="rdf_link" />
    <axis
      xyz="0 0 1" />
    <limit
      lower="0"
      upper="1.25"
      effort="0"
      velocity="0" />
  </joint>
  <link
    name="r_tip_link">
    <inertial>
      <origin
        xyz="-0.00104592121213923 0.00184222378959314 -4.44414470501808E-16"
        rpy="0 0 0" />
      <mass
        value="9.63413917385707E-05" />
      <inertia
        ixx="2.0016019067885E-09"
        ixy="6.47869811756383E-10"
        ixz="7.57635645960032E-24"
        iyy="1.67304493693444E-09"
        iyz="-9.39810472323535E-24"
        izz="2.11896979425827E-09" />
    </inertial>
    <visual>
      <origin
        xyz="0 0 0"
        rpy="0 0 0" />
      <geometry>
        <mesh
          filename="package://hand_rviz/urdf/meshes/r_tip_link.STL" />
      </geometry>
      <material
        name="">
        <color
          rgba="0.792156862745098 0.819607843137255 0.933333333333333 1" />
      </material>
    </visual>
    <collision>
      <origin
        xyz="0 0 0"
        rpy="0 0 0" />
      <geometry>
        <mesh
          filename="package://hand_rviz/urdf/meshes/r_tip_link.STL" />
      </geometry>
    </collision>
  </link>
  <joint
    name="r_tip"
    type="fixed">
    <origin
      xyz="0.00913233682828257 0 0"
      rpy="0 0 0" />
    <parent
      link="rdf_link" />
    <child
      link="r_tip_link" />
    <axis
      xyz="0 0 0" />
  </joint>
  <link
    name="pma_link">
    <inertial>
      <origin
        xyz="0.0054595149828438 -8.86628775930531E-05 0.000675699122759423"
        rpy="0 0 0" />
      <mass
        value="0.00377097300672915" />
      <inertia
        ixx="1.92751149082069E-07"
        ixy="3.86809745111146E-09"
        ixz="1.50762369878534E-08"
        iyy="2.98859887634649E-07"
        iyz="-5.17695482481916E-10"
        izz="2.60279570555227E-07" />
    </inertial>
    <visual>
      <origin
        xyz="0 0 0"
        rpy="0 0 0" />
      <geometry>
        <mesh
          filename="package://hand_rviz/urdf/meshes/pma_link.STL" />
      </geometry>
      <material
        name="">
        <color
          rgba="0.792156862745098 0.819607843137255 0.933333333333333 1" />
      </material>
    </visual>
    <collision>
      <origin
        xyz="0 0 0"
        rpy="0 0 0" />
      <geometry>
        <mesh
          filename="package://hand_rviz/urdf/meshes/pma_link.STL" />
      </geometry>
    </collision>
  </link>
  <joint
    name="pma_joint"
    type="revolute">
    <origin
      xyz="0.030085 -0.0405 0.11024"
      rpy="1.5708 -1.4573 0" />
    <parent
      link="hand_base_link" />
    <child
      link="pma_link" />
    <axis
      xyz="0 0 1" />
    <limit
      lower="-0.436"
      upper="0.436"
      effort="0"
      velocity="0" />
  </joint>
  <link
    name="pmf_link">
    <inertial>
      <origin
        xyz="0.0153264556452624 0.00013117022966441 -0.000214215915456326"
        rpy="0 0 0" />
      <mass
        value="0.00350627798987508" />
      <inertia
        ixx="7.49209011315719E-08"
        ixy="-2.7727406878371E-10"
        ixz="-1.59748483877381E-08"
        iyy="3.799529779382E-07"
        iyz="4.50760084554193E-11"
        izz="3.76775899782436E-07" />
    </inertial>
    <visual>
      <origin
        xyz="0 0 0"
        rpy="0 0 0" />
      <geometry>
        <mesh
          filename="package://hand_rviz/urdf/meshes/pmf_link.STL" />
      </geometry>
      <material
        name="">
        <color
          rgba="0.792156862745098 0.819607843137255 0.933333333333333 1" />
      </material>
    </visual>
    <collision>
      <origin
        xyz="0 0 0"
        rpy="0 0 0" />
      <geometry>
        <mesh
          filename="package://hand_rviz/urdf/meshes/pmf_link.STL" />
      </geometry>
    </collision>
  </link>
  <joint
    name="pmf_joint"
    type="revolute">
    <origin
      xyz="0.017 0 -0.000875"
      rpy="-1.5707963267949 0 0" />
    <parent
      link="pma_link" />
    <child
      link="pmf_link" />
    <axis
      xyz="0 0 1" />
    <limit
      lower="-1.57"
      upper="1.57"
      effort="0"
      velocity="0" />
  </joint>
  <link
    name="ppf_link">
    <inertial>
      <origin
        xyz="0.0110133857157522 -0.0013539573318288 4.13325359225128E-09"
        rpy="0 0 0" />
      <mass
        value="0.00108838501206663" />
      <inertia
        ixx="1.06723406101795E-08"
        ixy="4.16185682602898E-09"
        ixz="1.47097801103414E-14"
        iyy="1.13635444630546E-07"
        iyz="-1.28940560820316E-14"
        izz="1.21308280596702E-07" />
    </inertial>
    <visual>
      <origin
        xyz="0 0 0"
        rpy="0 0 0" />
      <geometry>
        <mesh
          filename="package://hand_rviz/urdf/meshes/ppf_link.STL" />
      </geometry>
      <material
        name="">
        <color
          rgba="0.792156862745098 0.819607843137255 0.933333333333333 1" />
      </material>
    </visual>
    <collision>
      <origin
        xyz="0 0 0"
        rpy="0 0 0" />
      <geometry>
        <mesh
          filename="package://hand_rviz/urdf/meshes/ppf_link.STL" />
      </geometry>
    </collision>
  </link>
  <joint
    name="ppf_joint"
    type="revolute">
    <origin
      xyz="0.031 0 0"
      rpy="0 0 1.17317577259539" />
    <parent
      link="pmf_link" />
    <child
      link="ppf_link" />
    <axis
      xyz="0 0 1" />
    <limit
      lower="-0.873"
      upper="1.57"
      effort="0"
      velocity="0" />
  </joint>
  <link
    name="pdf_link">
    <inertial>
      <origin
        xyz="-0.00394721685373974 -0.000117912575368528 -0.000103067960665844"
        rpy="0 0 0" />
      <mass
        value="0.00213606649935726" />
      <inertia
        ixx="5.37047745131982E-08"
        ixy="-1.93680926392119E-09"
        ixz="8.38609998331635E-10"
        iyy="1.74117813589534E-07"
        iyz="2.63405188882414E-11"
        izz="1.56263330743312E-07" />
    </inertial>
    <visual>
      <origin
        xyz="0 0 0"
        rpy="0 0 0" />
      <geometry>
        <mesh
          filename="package://hand_rviz/urdf/meshes/pdf_link.STL" />
      </geometry>
      <material
        name="">
        <color
          rgba="0.792156862745098 0.819607843137255 0.933333333333333 1" />
      </material>
    </visual>
    <collision>
      <origin
        xyz="0 0 0"
        rpy="0 0 0" />
      <geometry>
        <mesh
          filename="package://hand_rviz/urdf/meshes/pdf_link.STL" />
      </geometry>
    </collision>
  </link>
  <joint
    name="pdf_joint"
    type="revolute">
    <origin
      xyz="0.02618 0 0"
      rpy="0 0 0.397620554199505" />
    <parent
      link="ppf_link" />
    <child
      link="pdf_link" />
    <axis
      xyz="0 0 1" />
    <limit
      lower="0"
      upper="1.25"
      effort="0"
      velocity="0" />
  </joint>
  <link
    name="p_tip_link">
    <inertial>
      <origin
        xyz="-0.00104592121213926 0.00184222378959337 -2.63677968348475E-16"
        rpy="0 0 0" />
      <mass
        value="9.63413917385593E-05" />
      <inertia
        ixx="2.00160190678821E-09"
        ixy="6.47869811756375E-10"
        ixz="7.32904466230684E-24"
        iyy="1.67304493693428E-09"
        iyz="8.97525324661129E-24"
        izz="2.11896979425809E-09" />
    </inertial>
    <visual>
      <origin
        xyz="0 0 0"
        rpy="0 0 0" />
      <geometry>
        <mesh
          filename="package://hand_rviz/urdf/meshes/p_tip_link.STL" />
      </geometry>
      <material
        name="">
        <color
          rgba="0.792156862745098 0.819607843137255 0.933333333333333 1" />
      </material>
    </visual>
    <collision>
      <origin
        xyz="0 0 0"
        rpy="0 0 0" />
      <geometry>
        <mesh
          filename="package://hand_rviz/urdf/meshes/p_tip_link.STL" />
      </geometry>
    </collision>
  </link>
  <joint
    name="p_tip"
    type="fixed">
    <origin
      xyz="0.00913233682828257 0 0"
      rpy="0 0 0" />
    <parent
      link="pdf_link" />
    <child
      link="p_tip_link" />
    <axis
      xyz="0 0 0" />
  </joint>
</robot>